Unhandled exception in thread started by <function check_errors.<locals>.wrapper at 0x7f78156c4f28>
Traceback (most recent call last):
  File "/usr/local/python3/lib/python3.6/site-packages/django/utils/autoreload.py", line 225, in wrapper
    fn(*args, **kwargs)
  File "/usr/local/python3/lib/python3.6/site-packages/django/core/management/commands/runserver.py", line 120, in inner_run
    self.check(display_num_errors=True)
  File "/usr/local/python3/lib/python3.6/site-packages/django/core/management/base.py", line 364, in check
    include_deployment_checks=include_deployment_checks,
  File "/usr/local/python3/lib/python3.6/site-packages/django/core/management/base.py", line 351, in _run_checks
    return checks.run_checks(**kwargs)
  File "/usr/local/python3/lib/python3.6/site-packages/django/core/checks/registry.py", line 73, in run_checks
    new_errors = check(app_configs=app_configs)
  File "/usr/local/python3/lib/python3.6/site-packages/django/core/checks/urls.py", line 40, in check_url_namespaces_unique
    all_namespaces = _load_all_namespaces(resolver)
  File "/usr/local/python3/lib/python3.6/site-packages/django/core/checks/urls.py", line 57, in _load_all_namespaces
    url_patterns = getattr(resolver, 'url_patterns', [])
  File "/usr/local/python3/lib/python3.6/site-packages/django/utils/functional.py", line 36, in __get__
    res = instance.__dict__[self.name] = self.func(instance)
  File "/usr/local/python3/lib/python3.6/site-packages/django/urls/resolvers.py", line 536, in url_patterns
    patterns = getattr(self.urlconf_module, "urlpatterns", self.urlconf_module)
  File "/usr/local/python3/lib/python3.6/site-packages/django/utils/functional.py", line 36, in __get__
    res = instance.__dict__[self.name] = self.func(instance)
  File "/usr/local/python3/lib/python3.6/site-packages/django/urls/resolvers.py", line 529, in urlconf_module
    return import_module(self.urlconf_name)
  File "/usr/local/python3/lib/python3.6/importlib/__init__.py", line 126, in import_module
    return _bootstrap._gcd_import(name[level:], package, level)
  File "<frozen importlib._bootstrap>", line 978, in _gcd_import
  File "<frozen importlib._bootstrap>", line 961, in _find_and_load
  File "<frozen importlib._bootstrap>", line 950, in _find_and_load_unlocked
  File "<frozen importlib._bootstrap>", line 655, in _load_unlocked
  File "<frozen importlib._bootstrap_external>", line 674, in exec_module
  File "<frozen importlib._bootstrap_external>", line 781, in get_code
  File "<frozen importlib._bootstrap_external>", line 741, in source_to_code
  File "<frozen importlib._bootstrap>", line 205, in _call_with_frames_removed
  File "/root/xw/xwdjango-master/xwdjango/urls.py", line 25
    path("geo/index/",geo)
       ^
SyntaxError: invalid syntax
Performing system checks...

[15/Oct/2018 04:09:00] "GET /api/today/ HTTP/1.1" 200 43277
Not Found: /favicon.ico
[15/Oct/2018 04:09:01] "GET /favicon.ico HTTP/1.1" 404 2417
[15/Oct/2018 04:09:10] "GET /geo/index HTTP/1.1" 301 0
Internal Server Error: /geo/index/
Traceback (most recent call last):
  File "/usr/local/python3/lib/python3.6/site-packages/django/core/handlers/exception.py", line 35, in inner
    response = get_response(request)
  File "/usr/local/python3/lib/python3.6/site-packages/django/core/handlers/base.py", line 128, in _get_response
    response = self.process_exception_by_middleware(e, request)
  File "/usr/local/python3/lib/python3.6/site-packages/django/core/handlers/base.py", line 126, in _get_response
    response = wrapped_callback(request, *callback_args, **callback_kwargs)
  File "/root/xw/xwdjango-master/spider/views.py", line 72, in geo
    return render("geoIndex.html")
TypeError: render() missing 1 required positional argument: 'template_name'
[15/Oct/2018 04:09:10] "GET /geo/index/ HTTP/1.1" 500 63007
Performing system checks...

System check identified no issues (0 silenced).

You have 15 unapplied migration(s). Your project may not work properly until you apply the migrations for app(s): admin, auth, contenttypes, sessions, spider.
Run 'python manage.py migrate' to apply them.
October 15, 2018 - 04:08:58
Django version 2.0.4, using settings 'xwdjango.settings'
Starting development server at http://0.0.0.0:5000/
Quit the server with CONTROL-C.
